[2024-07-17T12:21:55.761+0000] {local_task_job_runner.py:120} INFO - ::group::Pre task execution logs
[2024-07-17T12:21:55.787+0000] {taskinstance.py:2076} INFO - Dependencies all met for dep_context=non-requeueable deps ti=<TaskInstance: simple_airflow_dag.task1 scheduled__2024-07-16T00:00:00+00:00 [queued]>
[2024-07-17T12:21:55.796+0000] {taskinstance.py:2076} INFO - Dependencies all met for dep_context=requeueable deps ti=<TaskInstance: simple_airflow_dag.task1 scheduled__2024-07-16T00:00:00+00:00 [queued]>
[2024-07-17T12:21:55.797+0000] {taskinstance.py:2306} INFO - Starting attempt 3 of 4
[2024-07-17T12:21:55.812+0000] {taskinstance.py:2330} INFO - Executing <Task(PythonOperator): task1> on 2024-07-16 00:00:00+00:00
[2024-07-17T12:21:55.818+0000] {warnings.py:112} WARNING - /home/***/.local/lib/python3.12/site-packages/***/task/task_runner/standard_task_runner.py:62: DeprecationWarning: This process (pid=129) is multi-threaded, use of fork() may lead to deadlocks in the child.
  pid = os.fork()

[2024-07-17T12:21:55.820+0000] {standard_task_runner.py:64} INFO - Started process 131 to run task
[2024-07-17T12:21:55.820+0000] {standard_task_runner.py:90} INFO - Running: ['***', 'tasks', 'run', 'simple_***_dag', 'task1', 'scheduled__2024-07-16T00:00:00+00:00', '--job-id', '11', '--raw', '--subdir', 'DAGS_FOLDER/simple_dag.py', '--cfg-path', '/tmp/tmpra1hxbxg']
[2024-07-17T12:21:55.822+0000] {standard_task_runner.py:91} INFO - Job 11: Subtask task1
[2024-07-17T12:21:55.872+0000] {task_command.py:426} INFO - Running <TaskInstance: simple_airflow_dag.task1 scheduled__2024-07-16T00:00:00+00:00 [running]> on host 8f6756dc8ee6
[2024-07-17T12:21:55.979+0000] {taskinstance.py:2648} INFO - Exporting env vars: AIRFLOW_CTX_DAG_OWNER='***' AIRFLOW_CTX_DAG_ID='simple_***_dag' AIRFLOW_CTX_TASK_ID='task1' AIRFLOW_CTX_EXECUTION_DATE='2024-07-16T00:00:00+00:00' AIRFLOW_CTX_TRY_NUMBER='3' AIRFLOW_CTX_DAG_RUN_ID='scheduled__2024-07-16T00:00:00+00:00'
[2024-07-17T12:21:56.031+0000] {taskinstance.py:430} INFO - ::endgroup::
[2024-07-17T12:21:56.032+0000] {logging_mixin.py:188} INFO - Error during unarchive: [Errno 2] No such file or directory: '/Users/pro/downloads/data.zip'
[2024-07-17T12:21:56.032+0000] {taskinstance.py:441} INFO - ::group::Post task execution logs
[2024-07-17T12:21:56.033+0000] {taskinstance.py:2905} ERROR - Task failed with exception
Traceback (most recent call last):
  File "/home/airflow/.local/lib/python3.12/site-packages/airflow/models/taskinstance.py", line 465, in _execute_task
    result = _execute_callable(context=context, **execute_callable_kwargs)
             ^^^^^^^^^^^^^^^^^^^^^^^^^^^^^^^^^^^^^^^^^^^^^^^^^^^^^^^^^^^^^
  File "/home/airflow/.local/lib/python3.12/site-packages/airflow/models/taskinstance.py", line 432, in _execute_callable
    return execute_callable(context=context, **execute_callable_kwargs)
           ^^^^^^^^^^^^^^^^^^^^^^^^^^^^^^^^^^^^^^^^^^^^^^^^^^^^^^^^^^^^
  File "/home/airflow/.local/lib/python3.12/site-packages/airflow/models/baseoperator.py", line 401, in wrapper
    return func(self, *args, **kwargs)
           ^^^^^^^^^^^^^^^^^^^^^^^^^^^
  File "/home/airflow/.local/lib/python3.12/site-packages/airflow/operators/python.py", line 235, in execute
    return_value = self.execute_callable()
                   ^^^^^^^^^^^^^^^^^^^^^^^
  File "/home/airflow/.local/lib/python3.12/site-packages/airflow/operators/python.py", line 252, in execute_callable
    return self.python_callable(*self.op_args, **self.op_kwargs)
           ^^^^^^^^^^^^^^^^^^^^^^^^^^^^^^^^^^^^^^^^^^^^^^^^^^^^^
  File "/opt/airflow/dags/simple_dag.py", line 59, in unarchive
    with zipfile.ZipFile(zip_file, 'r') as zip_ref:
         ^^^^^^^^^^^^^^^^^^^^^^^^^^^^^^
  File "/usr/local/lib/python3.12/zipfile/__init__.py", line 1331, in __init__
    self.fp = io.open(file, filemode)
              ^^^^^^^^^^^^^^^^^^^^^^^
FileNotFoundError: [Errno 2] No such file or directory: '/Users/pro/downloads/data.zip'
[2024-07-17T12:21:56.043+0000] {taskinstance.py:1206} INFO - Marking task as UP_FOR_RETRY. dag_id=simple_***_dag, task_id=task1, run_id=scheduled__2024-07-16T00:00:00+00:00, execution_date=20240716T000000, start_date=20240717T122155, end_date=20240717T122156
[2024-07-17T12:21:56.055+0000] {standard_task_runner.py:110} ERROR - Failed to execute job 11 for task task1 ([Errno 2] No such file or directory: '/Users/pro/downloads/data.zip'; 131)
[2024-07-17T12:21:56.084+0000] {local_task_job_runner.py:243} INFO - Task exited with return code 1
[2024-07-17T12:21:56.108+0000] {taskinstance.py:3503} INFO - 0 downstream tasks scheduled from follow-on schedule check
[2024-07-17T12:21:56.110+0000] {local_task_job_runner.py:222} INFO - ::endgroup::
